<?xml version="1.0" ?>
<!--******************************************************************
 ****** File automatically generated by generate_urdf.py script ******
 *********************************************************************-->
<robot name="JulietteY20MP" xmlns:xacro="http://www.ros.org/wiki/xacro">

	<link name="wheel_back_link">
	<inertial>
		<mass value="1.58028"/>
		<inertia ixx="0.00299756" ixy="6.3068e-07" ixz="5.56903e-06" iyy="0.00303229" iyz="-9.0408e-07" izz="0.00296585"/>
		<origin rpy="0 0 0" xyz="0 0 0"/>
	</inertial>
	<xacro:insert_visu_WheelB_link/>
	</link>

	<joint name="wheel_back_joint" type="continuous">
		<origin rpy="0.0 0.0 1.57" xyz="-0.17 0 -0.264"/>
		<parent link="Tibia"/>
		<child link="wheel_back_link"/>
		<axis xyz="1.0 0.0 0.0"/>
		<!-- <limit effort="3.25" lower="0" upper="0" velocity="6.28319"/> -->
	</joint>
	
	<link name="wheel_right_link">
	<inertial>
		<mass value="1.58028"/>
		<inertia ixx="0.00299756" ixy="6.3068e-07" ixz="5.56903e-06" iyy="0.00303229" iyz="-9.0408e-07" izz="0.00296585"/>
		<origin rpy="0 0 0" xyz="0 0 0"/>
	</inertial>
	<xacro:insert_visu_WheelFR_link/>
	</link>

	<joint name="wheel_right_joint" type="continuous">
		<origin xyz="0.09 -0.155 -0.264" rpy="0.0 0.0 1.57"/>
		<parent link="Tibia"/>
		<child link="wheel_right_link"/>
		<axis xyz="1.0 0.0 0.0"/>
		<!-- <limit effort="3.25" lower="0" upper="0" velocity="6.28319"/> -->
	</joint>
	
	<link name="wheel_left_link">
	<inertial>
		<mass value="1.58028"/>
		<inertia ixx="0.00299756" ixy="6.3068e-07" ixz="5.56903e-06" iyy="0.00303229" iyz="-9.0408e-07" izz="0.00296585"/>
		<origin rpy="0 0 0" xyz="0 0 0"/>
	</inertial>
	<xacro:insert_visu_WheelFL_link/>
	</link>
	
	<joint name="wheel_left_joint" type="continuous">
		<origin xyz="0.09 0.155 -0.264" rpy="0.0 0.0 1.57"/>
		<parent link="Tibia"/>
		<child link="wheel_left_link"/>
		<axis xyz="1.0 0.0 0.0"/>
		<!-- <limit effort="3.25" lower="0" upper="0" velocity="6.28319"/> -->
	</joint>

</robot>
